<robot name="mycar">
    <link name="base_link"><!-- 底盘 -->
        <visual>
            <geometry>
                <box size="0.5 0.2 0.1" />
            </geometry>
            <origin xyz="0 0 0.05" rpy="0 0 0" />
            <material name="car_color1">
                <color rgba="0.8 0.5 0 0.5" />
            </material>
        </visual>
    </link>
    <link name="camera"> <!-- 摄像头 -->
        <visual>
            <geometry>
                <box size="0.02 0.05 0.05" />
            </geometry>
            <origin xyz="0 0 0.075" rpy="0 0 0" />
            <material name="camare_color2">
                <color rgba="0 0 1 0.5" />
            </material>
        </visual>
    </link>
    <!-- 关节 -->
    <joint name="camera2base" type="continuous">
        <parent link="base_link"/>
        <child link="camera" />
        <!-- 需要计算两个 link 的物理中心之间的偏移量 -->
        <!--"0.5 0.2 0.1"—考虑物理中心—"0.02 0.05 0.05"   -->
        <origin xyz="0.2 0 0.075" rpy="0 0 0" />
        <axis xyz="0 0 1" />   <!-- 旋转参考坐标轴 -->
    </joint>

</robot>